Workbook

Sheet TABLEAU DE BORD
A1: REGISTRE GLOBAL & TABLEAU DE BORD - RARID JOURNAL
A3: Total Articles | B3: En Relecture | C3: En Révision | D3: Acceptés / Publiés | E3: Rejetés
A4: =COUNTA(A7:A13) -> 4 | B4: =COUNTIF(E7:E13,"Acceptation avec corrections") -> 1 | C4: =COUNTIF(E7:E13,"Révision majeure") -> 1 | D4: =COUNTIF(E7:E13,"Acceptation")+COUNTIF(E7:E13,"Publié") -> 1 | E4: =COUNTIF(E7:E13,"Rejet") -> 1
A6: ID Article | B6: Titre de l'Article | C6: Auteur Correspondant | D6: Domaine Thématique | E6: Statut Global | F6: Date Soumission | G6: Lien Onglet | H6: Pays | I6: Institution | J6: Email/Téléphone | K6: Solde
A7: =IF(B7<>"", "REV-2026-" & TEXT(ROWS($A$7:A7),"000"),"") -> REV-2026-001 | B7: Étude sur l'impact des technologies émergentes en Afrique Central | C7: Dr. Alain Dupont | D7: Innovations et technologies | E7: Rejet | F7: 2026-08-15 | G7: =HYPERLINK("#'"&A7&"'!A1","Accéder à la fiche →") -> Accéder à la fiche →
A8: =IF(B8<>"", "REV-2026-" & TEXT(ROWS($A$7:A8),"000"),"") -> REV-2026-002 | B8: Analyse des politiques publiques de santé et environnement | C8: Dr. Chantal Etoa | D8: Santé et environnement | E8: Acceptation | F8: 2026-08-16 | G8: =HYPERLINK("#'"&A8&"'!A1","Accéder à la fiche →") -> Accéder à la fiche →
A9: =IF(B9<>"", "REV-2026-" & TEXT(ROWS($A$7:A9),"000"),"") -> REV-2026-003 | B9: Cadre juridique de la transformation digitale des PME | C9: Prof. Bernard Kamga | D9: Gouvernance, Droit et Politique Publique | E9: Acceptation avec corrections | F9: 2026-08-01 | G9: =HYPERLINK("#'"&A9&"'!A1","Accéder à la fiche →") -> Accéder à la fiche →
A10: =IF(B10<>"", "REV-2026-" & TEXT(ROWS($A$7:A10),"000"),"") -> REV-2026-004 | B10: Infrastructures routières et développement durable à Douala | C10: Ing. Marc Nsangou | D10: Infrastructures et développement | E10: Révision majeure | F10: 2026-07-20 | G10: =HYPERLINK("#'"&A10&"'!A1","Accéder à la fiche →") -> Accéder à la fiche →

Sheet MODELE_ARTICLE
A1: FICHE DE SUIVI AUTEUR - RARID JOURNAL
A2: ID ARTICLE : | B2: =IFERROR(MID(CELL("nomfichier",A1), FIND("]",CELL("nomfichier",A1))+1,31),"") -> MODELE_ARTICLE | D2: STATUT GLOBAL : | E2: =IFERROR(VLOOKUP(B2,'TABLEAU DE BORD'!A:G,5,FALSE),"") | G2: =HYPERLINK("#'TABLEAU DE BORD'!A1", "🏠 Retour au Tableau de Bord") -> 🏠 Retour au Tableau de Bord
A3: TITRE : | B3: =IFERROR(VLOOKUP(B2,'TABLEAU DE BORD'!A:G,2,FALSE),"")
A4: AUTEUR CORRESPONDANT : | B4: =IFERROR(VLOOKUP(B2,'TABLEAU DE BORD'!A:G,3,FALSE),"") | D4: EMAIL / TEL : | E4: =IFERROR(VLOOKUP(B2,'TABLEAU DE BORD'!A:G,10,FALSE),"")
A5: INSTITUTION : | B5: =IFERROR(VLOOKUP(B2,'TABLEAU DE BORD'!A:G,9,FALSE),"") | D5: PAYS : | E5: =IFERROR(VLOOKUP(B2,'TABLEAU DE BORD'!A:G,8,FALSE),"")
A6: DOMAINE THÉMATIQUE : | B6: =IFERROR(VLOOKUP(B2,'TABLEAU DE BORD'!A:G,4,FALSE),"") | D6: SOLDE | E6: =IFERROR(VLOOKUP(B2,'TABLEAU DE BORD'!A:G,11,FALSE),"")
A8: ZONE 2 : CO-AUTEURS & CONTRIBUTIONS (CRediT)
A9: N° | B9: Nom & Prénom | C9: Institution | D9: Email | E9: Rôle Crédit | F9: FDR Signé (O/N) | G9: Notes
A10: 1 | F10: Non
A11: 2 | F11: Non
A12: 3 | F12: Non
A13: 4 | F13: Non
A15: ZONE 3 : SUIVI DU PROCESSUS ÉDITORIAL
A16: Étape | B16: Date Prévue | C16: Date Réelle | D16: Délai (Jours) | E16: Responsable | F16: Statut | G16: Commentaires
A17: 1. Accusé de réception | D17: =IF(ISBLANK(C17),"",C17-B17) | E17: Secrétariat | F17: En attente
A18: 2. Check anti-plagiat | D18: =IF(ISBLANK(C18),"",C18-B18) | E18: Rédacteur en chef | F18: En attente
A19: 3. Envoi aux relecteurs | D19: =IF(ISBLANK(C19),"",C19-B19) | E19: Comité Éditorial | F19: En attente
A20: 4. Retour relecteur 1 | D20: =IF(ISBLANK(C20),"",C20-B20) | E20: Relecteur 1 | F20: En attente
A21: 5. Retour relecteur 2 | D21: =IF(ISBLANK(C21),"",C21-B21) | E21: Relecteur 2 | F21: En attente
A22: 6. Décision 1 | D22: =IF(ISBLANK(C22),"",C22-B22) | E22: Rédacteur en chef | F22: En attente
A23: 7. Retour auteur (Révisions) | D23: =IF(ISBLANK(C23),"",C23-B23) | E23: Auteur correspondant | F23: En attente
A24: 8. Décision finale | D24: =IF(ISBLANK(C24),"",C24-B24) | E24: Comité Éditorial | F24: En attente
A25: 9. Envoi épreuves (Mise en page) | D25: =IF(ISBLANK(C25),"",C25-B25) | E25: Secrétariat | F25: En attente
A26: 10. BAT Auteur | D26: =IF(ISBLANK(C26),"",C26-B26) | E26: Auteur correspondant | F26: En attente
A27: 11. Publication | D27: =IF(ISBLANK(C27),"",C27-B27) | E27: Comité Éditorial | F27: En attente
A29: ZONE 4 : DOCUMENTS & CONFORMITÉ
A30: Document requis | B30: Reçu (O/N) | C30: Date Réception | D30: Lien / Emplacement Fichier | E30: Colonne1 | F30: Notes & Format | G30: Colonne2
A31: Manuscrit version finale | B31: Non | F31: Format .docx + .pdf
A32: Figures & Tableaux HD | B32: Non | F32: 300 DPI, PNG/TIFF
A33: Formulaire Transfert de Droits (FDR) | B33: Non | F33: Signé par tous les auteurs
A34: Déclaration Conflit d'intérêts | B34: Non | F34: Formulaire RARID rempli
A35: Approbation éthique / CPP | B35: Non | F35: N° CPP si étude humaine/animale
A36: Données brutes / Dépôt | B36: Non | F36: Lien Zenodo / OSF
A39: ZONE 5 : HISTORIQUE DE COMMUNICATION & RELANCES
A40: Action / Relance | B40: Date Prévue | C40: Date Effective | D40: Fait par | E40: Canal / Support | F40: Statut / Résultat | G40: Remarques
A41: Accusé de réception envoyé | D41: Secrétariat | E41: Email | F41: En attente
A42: Relance Relecteur 1 | D42: Secrétariat | E42: Email | F42: En attente | G42: Rappel J+7
A43: Relance Relecteur 2 | D43: Secrétariat | E43: Email | F43: En attente | G43: Rappel J+7
A44: Notification Décision 1 | D44: Rédacteur en Chef | E44: Email | F44: En attente
A47: ZONE 6 : NOTES / OBSERVATIONS / BLOQUAGES
...

Sheet REV-2026-001
A1: FICHE DE SUIVI AUTEUR - RARID JOURNAL
A2: ID ARTICLE : | B2: =IFERROR(MID(CELL("nomfichier",A1), FIND("]",CELL("nomfichier",A1))+1,31),"") -> REV-2026-001 | D2: STATUT GLOBAL : | E2: =IFERROR(VLOOKUP(B2,'TABLEAU DE BORD'!A:G,5,FALSE),"") -> Rejet | G2: =HYPERLINK("#'TABLEAU DE BORD'!A1", "🏠 Retour au Tableau de Bord") -> 🏠 Retour au Tableau de Bord
A3: TITRE : | B3: =IFERROR(VLOOKUP(B2,'TABLEAU DE BORD'!A:G,2,FALSE),"") -> Étude sur l'impact des technologies émergentes en Afrique Central
A4: AUTEUR CORRESPONDANT : | B4: =IFERROR(VLOOKUP(B2,'TABLEAU DE BORD'!A:G,3,FALSE),"") -> Dr. Alain Dupont | D4: EMAIL / TEL : | E4: =IFERROR(VLOOKUP(B2,'TABLEAU DE BORD'!A:G,10,FALSE),"")
A5: INSTITUTION : | B5: =IFERROR(VLOOKUP(B2,'TABLEAU DE BORD'!A:G,9,FALSE),"") | D5: PAYS : | E5: =IFERROR(VLOOKUP(B2,'TABLEAU DE BORD'!A:G,8,FALSE),"")
A6: DOMAINE THÉMATIQUE : | B6: =IFERROR(VLOOKUP(B2,'TABLEAU DE BORD'!A:G,4,FALSE),"") -> Innovations et technologies | D6: SOLDE | E6: =IFERROR(VLOOKUP(B2,'TABLEAU DE BORD'!A:G,11,FALSE),"")
A8: ZONE 2 : CO-AUTEURS & CONTRIBUTIONS (CRediT)
A9: N° | B9: Nom & Prénom | C9: Institution | D9: Email | E9: Rôle Crédit | F9: FDR Signé (O/N) | G9: Notes
A10: 1 | F10: Non
A11: 2 | F11: Non
A12: 3 | F12: Non
A13: 4 | F13: Non
A15: ZONE 3 : SUIVI DU PROCESSUS ÉDITORIAL
A16: Étape | B16: Date Prévue | C16: Date Réelle | D16: Délai (Jours) | E16: Responsable | F16: Statut | G16: Commentaires
A17: 1. Accusé de réception | D17: =IF(ISBLANK(C17),"",C17-B17) | E17: Secrétariat | F17: En attente
A18: 2. Check anti-plagiat | D18: =IF(ISBLANK(C18),"",C18-B18) | E18: Rédacteur en chef | F18: En attente
A19: 3. Envoi aux relecteurs | D19: =IF(ISBLANK(C19),"",C19-B19) | E19: Comité Éditorial | F19: En attente
A20: 4. Retour relecteur 1 | D20: =IF(ISBLANK(C20),"",C20-B20) | E20: Relecteur 1 | F20: En attente
A21: 5. Retour relecteur 2 | D21: =IF(ISBLANK(C21),"",C21-B21) | E21: Relecteur 2 | F21: En attente
A22: 6. Décision 1 | D22: =IF(ISBLANK(C22),"",C22-B22) | E22: Rédacteur en chef | F22: En attente
A23: 7. Retour auteur (Révisions) | D23: =IF(ISBLANK(C23),"",C23-B23) | E23: Auteur correspondant | F23: En attente
A24: 8. Décision finale | D24: =IF(ISBLANK(C24),"",C24-B24) | E24: Comité Éditorial | F24: En attente
A25: 9. Envoi épreuves (Mise en page) | D25: =IF(ISBLANK(C25),"",C25-B25) | E25: Secrétariat | F25: En attente
A26: 10. BAT Auteur | D26: =IF(ISBLANK(C26),"",C26-B26) | E26: Auteur correspondant | F26: En attente
A27: 11. Publication | D27: =IF(ISBLANK(C27),"",C27-B27) | E27: Comité Éditorial | F27: En attente
A29: ZONE 4 : DOCUMENTS & CONFORMITÉ
A30: Document requis | B30: Reçu (O/N) | C30: Date Réception | D30: Lien / Emplacement Fichier | E30: Colonne1 | F30: Notes & Format | G30: Colonne2
A31: Manuscrit version finale | B31: Non | F31: Format .docx + .pdf
A32: Figures & Tableaux HD | B32: Non | F32: 300 DPI, PNG/TIFF
A33: Formulaire Transfert de Droits (FDR) | B33: Non | F33: Signé par tous les auteurs
A34: Déclaration Conflit d'intérêts | B34: Non | F34: Formulaire RARID rempli
A35: Approbation éthique / CPP | B35: Non | F35: N° CPP si étude humaine/animale
A36: Données brutes / Dépôt | B36: Non | F36: Lien Zenodo / OSF
A39: ZONE 5 : HISTORIQUE DE COMMUNICATION & RELANCES
A40: Action / Relance | B40: Date Prévue | C40: Date Effective | D40: Fait par | E40: Canal / Support | F40: Statut / Résultat | G40: Remarques
A41: Accusé de réception envoyé | D41: Secrétariat | E41: Email | F41: En attente
A42: Relance Relecteur 1 | D42: Secrétariat | E42: Email | F42: En attente | G42: Rappel J+7
A43: Relance Relecteur 2 | D43: Secrétariat | E43: Email | F43: En attente | G43: Rappel J+7
A44: Notification Décision 1 | D44: Rédacteur en Chef | E44: Email | F44: En attente
A47: ZONE 6 : NOTES / OBSERVATIONS / BLOQUAGES
...
